Traceback (most recent call last):
  File "/home/jca92/anaconda3/envs/shuyu-paper/lib/python3.11/site-packages/jupyter_core/utils/__init__.py", line 154, in wrapped
    asyncio.get_running_loop()
RuntimeError: no running event loop

During handling of the above exception, another exception occurred:

Traceback (most recent call last):
  File "/home/jca92/anaconda3/envs/shuyu-paper/lib/python3.11/site-packages/jupyter_cache/executors/utils.py", line 58, in single_nb_execution
    executenb(
  File "/home/jca92/anaconda3/envs/shuyu-paper/lib/python3.11/site-packages/nbclient/client.py", line 1319, in execute
    return NotebookClient(nb=nb, resources=resources, km=km, **kwargs).execute()
           ^^^^^^^^^^^^^^^^^^^^^^^^^^^^^^^^^^^^^^^^^^^^^^^^^^^^^^^^^^^^^^^^^^^^^
  File "/home/jca92/anaconda3/envs/shuyu-paper/lib/python3.11/site-packages/jupyter_core/utils/__init__.py", line 158, in wrapped
    return loop.run_until_complete(inner)
           ^^^^^^^^^^^^^^^^^^^^^^^^^^^^^^
  File "/home/jca92/anaconda3/envs/shuyu-paper/lib/python3.11/asyncio/base_events.py", line 654, in run_until_complete
    return future.result()
           ^^^^^^^^^^^^^^^
  File "/home/jca92/anaconda3/envs/shuyu-paper/lib/python3.11/site-packages/nbclient/client.py", line 709, in async_execute
    await self.async_execute_cell(
  File "/home/jca92/anaconda3/envs/shuyu-paper/lib/python3.11/site-packages/nbclient/client.py", line 1062, in async_execute_cell
    await self._check_raise_for_error(cell, cell_index, exec_reply)
  File "/home/jca92/anaconda3/envs/shuyu-paper/lib/python3.11/site-packages/nbclient/client.py", line 918, in _check_raise_for_error
    raise CellExecutionError.from_cell_and_msg(cell, exec_reply_content)
nbclient.exceptions.CellExecutionError: An error occurred while executing the following cell:
------------------
display_noisy_diffraction(data,
    folder_path=os.path.join(folder_path, "figures/"),
    noise_level=[0, 0.25, 0.6],
)
------------------


[31m---------------------------------------------------------------------------[39m
[31mNameError[39m                                 Traceback (most recent call last)
[36mCell[39m[36m [39m[32mIn[10][39m[32m, line 2[39m
[32m      1[39m display_noisy_diffraction(data,
[32m----> [39m[32m2[39m     folder_path=os.path.join([43mfolder_path[49m, [33m"[39m[33mfigures/[39m[33m"[39m),
[32m      3[39m     noise_level=[[32m0[39m, [32m0.25[39m, [32m0.6[39m],
[32m      4[39m )

[31mNameError[39m: name 'folder_path' is not defined

